<?xml version='1.0'?>
<sdf version='1.5'>
   
  <model name='mobidik'>      
   

   <link name='base_link'>    
	     
	   
      <inertial>
        <mass>4*50.0</mass>
        <inertia> <!-- inertias are tricky to compute -->
          <!-- http://gazebosim.org/tutorials?tut=inertia&cat=build_robot -->
          <ixx>0.083*4*50.0*1.01</ixx>       <!-- for a box: ixx = 0.083 * mass * (y*y + z*z) -->
          <ixy>0.0</ixy>         <!-- for a box: ixy = 0 -->
          <ixz>0.0</ixz>         <!-- for a box: ixz = 0 -->
          <iyy>0.083*4*50.0*1.01</iyy>       <!-- for a box: iyy = 0.083 * mass * (x*x + z*z) -->
          <iyz>0.0</iyz>         <!-- for a box: iyz = 0 -->
          <izz>0.083*4*50.0*2</izz>       <!-- for a box: izz = 0.083 * mass * (x*x + y*y) -->
        </inertia>
      </inertial>
	   
      <collision name='base_link_collision'>
        <pose>0.325 0 0.195 0 0 0</pose>
        <geometry>
          <box>
            <size>0.82 0.72 0.2</size>
          </box>
        </geometry>        
      </collision>
      <visual name='base_link_visual'>	    
		<pose>0.325 0 0.195 0 0 0</pose>
        <geometry>
          <box>
            <size>0.82 0.72 0.2</size>
          </box>
        </geometry> 
	     <material>
			<ambient>0 0 1 1</ambient>
			<diffuse>0 0 1 1</diffuse>
			<specular>0.1 0.1 0.1 1</specular>
			<emissive>0 0 0 0</emissive>
		</material>        
      </visual>   
      
        
      
<!-- ********************** Bars ***************************** -->    

      <visual name='base_barv1_visual'>	    
        <pose>-0.06 0.335 0.95 0 0 0</pose>
          <geometry>
            <cylinder>
              <radius>.02</radius>
              <length>1.5</length>
            </cylinder>
          </geometry>
	     <material>
			<ambient>0 0 1 1</ambient>
			<diffuse>0 0 1 1</diffuse>
			<specular>0.1 0.1 0.1 1</specular>
			<emissive>0 0 0 0</emissive>
		</material>        
      </visual>  
      
      <visual name='base_barv2_visual'>	    
        <pose>-0.06 -0.335 0.95 0 0 0</pose>
          <geometry>
            <cylinder>
              <radius>.02</radius>
              <length>1.5</length>
            </cylinder>
          </geometry>
	     <material>
			<ambient>0 0 1 1</ambient>
			<diffuse>0 0 1 1</diffuse>
			<specular>0.1 0.1 0.1 1</specular>
			<emissive>0 0 0 0</emissive>
		</material>        
      </visual>    
      
      <visual name='base_barv1_2_visual'>	    
        <pose>-0.06 0.0 0.95 0 0 0</pose>
          <geometry>
            <cylinder>
              <radius>.02</radius>
              <length>1.5</length>
            </cylinder>
          </geometry>
	     <material>
			<ambient>0 0 1 1</ambient>
			<diffuse>0 0 1 1</diffuse>
			<specular>0.1 0.1 0.1 1</specular>
			<emissive>0 0 0 0</emissive>
		</material>        
      </visual>        
      
      <visual name='base_barv3_visual'>	    
        <pose>0.71 0.335 0.95 0 0 0</pose>
          <geometry>
            <cylinder>
              <radius>.02</radius>
              <length>1.5</length>
            </cylinder>
          </geometry>
	     <material>
			<ambient>0 0 1 1</ambient>
			<diffuse>0 0 1 1</diffuse>
			<specular>0.1 0.1 0.1 1</specular>
			<emissive>0 0 0 0</emissive>
		</material>        
      </visual>  
      
      <visual name='base_barv4_visual'>	    
        <pose>0.71 -0.335 0.95 0 0 0</pose>
          <geometry>
            <cylinder>
              <radius>.02</radius>
              <length>1.5</length>
            </cylinder>
          </geometry>
	     <material>
			<ambient>0 0 1 1</ambient>
			<diffuse>0 0 1 1</diffuse>
			<specular>0.1 0.1 0.1 1</specular>
			<emissive>0 0 0 0</emissive>
		</material>        
      </visual>  
      
      <visual name='base_barv2_4_visual'>	    
        <pose>0.35 -0.335 0.95 0 0 0</pose>
          <geometry>
            <cylinder>
              <radius>.02</radius>
              <length>1.5</length>
            </cylinder>
          </geometry>
	     <material>
			<ambient>0 0 1 1</ambient>
			<diffuse>0 0 1 1</diffuse>
			<specular>0.1 0.1 0.1 1</specular>
			<emissive>0 0 0 0</emissive>
		</material>        
      </visual>    
      
      <visual name='base_barv1_4_visual'>	    
        <pose>0.35 0.335 0.95 0 0 0</pose>
          <geometry>
            <cylinder>
              <radius>.02</radius>
              <length>1.5</length>
            </cylinder>
          </geometry>
	     <material>
			<ambient>0 0 1 1</ambient>
			<diffuse>0 0 1 1</diffuse>
			<specular>0.1 0.1 0.1 1</specular>
			<emissive>0 0 0 0</emissive>
		</material>        
      </visual>  

<!-- ********************** trays ***************************** -->       
      <visual name='tray1_visual'>	    
		<pose>0.325 0 0.9 0 0 0</pose>
        <geometry>
          <box>
            <size>0.82 0.72 0.05</size>
          </box>
        </geometry> 
	     <material>
			<ambient>0 0 1 1</ambient>
			<diffuse>0 0 1 1</diffuse>
			<specular>0.1 0.1 0.1 1</specular>
			<emissive>0 0 0 0</emissive>
		</material>        
      </visual>    
      <visual name='tray2_visual'>	    
		<pose>0.325 0 1.7 0 0 0</pose>
        <geometry>
          <box>
            <size>0.82 0.72 0.05</size>
          </box>
        </geometry> 
	     <material>
			<ambient>0 0 1 1</ambient>
			<diffuse>0 0 1 1</diffuse>
			<specular>0.1 0.1 0.1 1</specular>
			<emissive>0 0 0 0</emissive>
		</material>        
      </visual>        
      
<!-- ********************** Casters ***************************** -->      
      
		<collision name='caster_top_left_collision'>
            <pose>0.65 0.285 0.06 0 0 0</pose>
            <geometry>
                <sphere>
                <radius>.06</radius>
              </sphere>
            </geometry>

            <surface>
              <friction>
                <ode>
                  <mu>0</mu>
                  <mu2>0</mu2>
                  <slip1>1.0</slip1>
                  <slip2>1.0</slip2>
                </ode>
              </friction>
            </surface>
          </collision>

          <visual name='caster_top_left_visual'>
			<pose>0.65 0.285 0.06 0 0 0</pose>
            <geometry>
                <sphere>
                <radius>.06</radius>
              </sphere>
            </geometry>

          </visual>      
          
      
		<collision name='caster_top_right_collision'>
            <pose>0.65 -0.285 0.06 0 0 0</pose>
            <geometry>
                <sphere>
                <radius>.06</radius>
              </sphere>
            </geometry>

            <surface>
              <friction>
                <ode>
                  <mu>0</mu>
                  <mu2>0</mu2>
                  <slip1>1.0</slip1>
                  <slip2>1.0</slip2>
                </ode>
              </friction>
            </surface>
          </collision>

          <visual name='caster_top_right_visual'>
			<pose>0.65 -0.285 0.06 0 0 0</pose>
            <geometry>
                <sphere>
                <radius>.06</radius>
              </sphere>
            </geometry>

          </visual>            
          
     <gravity>1</gravity>
      <self_collide>0</self_collide>

   
      </link>
          
<!-- ********************** Wheels ***************************** -->                
      <link name="left_rear_wheel">
        <pose>0 0.285 0.06 0 1.5707 1.5707</pose>
        <collision name="collision">
          <geometry>
            <cylinder>
              <radius>.06</radius>
              <length>.05</length>
            </cylinder>
          </geometry>
	  <surface>
	  <friction>
	    <ode>
<!--	      <mu>100.0</mu>
	      <mu2>100000.0</mu2>
	      <slip1>0.0</slip1>
	      <slip2>0.0</slip2>-->
              <mu>0.0</mu>
              <mu2>0.0</mu2>
              <slip1>1.0</slip1>
              <slip2>1.0</slip2>                
	    </ode>
	  </friction>	  
	  <contact>
	    <ode><min_depth>0.003</min_depth></ode>
	  </contact>	  
	</surface>
        </collision>
        <visual name="visual">
          <geometry>
            <cylinder>
              <radius>.06</radius>
              <length>.05</length>
            </cylinder>
          </geometry>
        </visual>
      </link>          
      
      <link name="right_rear_wheel">
        <pose>0 -0.285 0.06 0 1.5707 1.5707</pose>
        <collision name="collision">
          <geometry>
            <cylinder>
              <radius>.06</radius>
              <length>.05</length>
            </cylinder>
          </geometry>
	  <surface>
	    <friction>
	      <ode>
<!--          <mu>100.0</mu>
              <mu2>100000.0</mu2>
              <slip1>0.0</slip1>
              <slip2>0.0</slip2>-->
              <mu>0.0</mu>
              <mu2>0.0</mu2>
              <slip1>1.0</slip1>
              <slip2>1.0</slip2>   
	      </ode>
	    </friction>
	    <contact>
	      <ode><min_depth>0.003</min_depth></ode>
	    </contact>		    
	  </surface>	  
        </collision>
        <visual name="visual">
          <geometry>
            <cylinder>
              <radius>.06</radius>
              <length>.05</length>
            </cylinder>
          </geometry>
        </visual>
      </link>        
 
       <joint type="revolute" name="left_wheel_hinge">
        <pose>0 0 -0.085 0 0 0</pose>
        <child>left_rear_wheel</child>
        <parent>base_link</parent>
        <axis>
          <xyz>0 0 1</xyz>
        </axis>
      </joint>

      <joint type="revolute" name="right_wheel_hinge">
        <pose>0 0 -0.085 0 0 0</pose>
        <child>right_rear_wheel</child>
        <parent>base_link</parent>
        <axis>
          <xyz>0 0 1</xyz>
        </axis>
      </joint>
  
<!-- ********************** Other parameters ***************************** -->

   <plugin name="Odometry_Plugin" filename="libOdometry_Plugin.so">
       <updateRate>30.0</updateRate>
       <veltopicName>/load/cmd_vel</veltopicName>       
       <odomtopicName>/load/odom_incomplete</odomtopicName>       
       <robotBaseFrame>/load/base_link</robotBaseFrame>
       <odomFrame>/load/odom</odomFrame>      
   </plugin>    


  </model>

  </sdf>
